Workbook

Sheet Detailed Steps
A1: Ticket ID | B1: Epic | C1: Ticket / Task | D1: Step # | E1: Detailed implementation step | F1: Effort (hours) | G1: Effort (days) | H1: Status | I1: Evidence / notes
A2: VCCI-AI-01 | B2: VCCI Desktop | C2: Develop Java Swing AI Chatbot client | D2: 1 | E2: Create Swing window and layout | F2: 4 | G2: =F2/8 -> 0.5 | H2: Implemented / verify acceptance | I2: Planning estimate; not time logged
A3: VCCI-AI-01 | B3: VCCI Desktop | C3: Develop Java Swing AI Chatbot client | D3: 2 | E3: Build prompt and response panels | F3: 6 | G3: =F3/8 -> 0.75 | H3: Implemented / verify acceptance
A4: VCCI-AI-01 | B4: VCCI Desktop | C4: Develop Java Swing AI Chatbot client | D4: 3 | E4: Connect chatbot to VCCI launcher | F4: 4 | G4: =F4/8 -> 0.5 | H4: Implemented / verify acceptance
A5: VCCI-AI-01 | B5: VCCI Desktop | C5: Develop Java Swing AI Chatbot client | D5: 4 | E5: Implement background message dispatch | F5: 6 | G5: =F5/8 -> 0.75 | H5: Implemented / verify acceptance
A6: VCCI-AI-01 | B6: VCCI Desktop | C6: Develop Java Swing AI Chatbot client | D6: 5 | E6: Test launch and response display | F6: 4 | G6: =F6/8 -> 0.5 | H6: Implemented / verify acceptance
A7: VCCI-AI-02 | B7: VCCI Desktop | C7: Implement agent selection and chat controls | D7: 1 | E7: Populate dropdown with agent entries | F7: 3 | G7: =F7/8 -> 0.375 | H7: Implemented / verify acceptance | I7: Planning estimate; not time logged
A8: VCCI-AI-02 | B8: VCCI Desktop | C8: Implement agent selection and chat controls | D8: 2 | E8: Add AUTO and manual selection behavior | F8: 3 | G8: =F8/8 -> 0.375 | H8: Implemented / verify acceptance
A9: VCCI-AI-02 | B9: VCCI Desktop | C9: Implement agent selection and chat controls | D9: 3 | E9: Wire Refresh and New Chat actions | F9: 2 | G9: =F9/8 -> 0.25 | H9: Implemented / verify acceptance
A10: VCCI-AI-02 | B10: VCCI Desktop | C10: Implement agent selection and chat controls | D10: 4 | E10: Wire Send and Close actions | F10: 2 | G10: =F10/8 -> 0.25 | H10: Implemented / verify acceptance
A11: VCCI-AI-02 | B11: VCCI Desktop | C11: Implement agent selection and chat controls | D11: 5 | E11: Test button behavior and state | F11: 2 | G11: =F11/8 -> 0.25 | H11: Implemented / verify acceptance
A12: VCCI-AI-03 | B12: VCCI Desktop | C12: Display dynamic friendly agent names | D12: 1 | E12: Read friendly names from discovery metadata | F12: 2 | G12: =F12/8 -> 0.25 | H12: Implemented / verify acceptance | I12: VCCI a52acac
A13: VCCI-AI-03 | B13: VCCI Desktop | C13: Display dynamic friendly agent names | D13: 2 | E13: Preserve internal agent IDs separately | F13: 2 | G13: =F13/8 -> 0.25 | H13: Implemented / verify acceptance
A14: VCCI-AI-03 | B14: VCCI Desktop | C14: Display dynamic friendly agent names | D14: 3 | E14: Update AgentInfo and dropdown renderer | F14: 2 | G14: =F14/8 -> 0.25 | H14: Implemented / verify acceptance
A15: VCCI-AI-03 | B15: VCCI Desktop | C15: Display dynamic friendly agent names | D15: 4 | E15: Verify refresh and renamed agents | F15: 2 | G15: =F15/8 -> 0.25 | H15: Implemented / verify acceptance
A16: VCCI-AI-04 | B16: VCCI Desktop | C16: Implement conversation context and session tracking | D16: 1 | E16: Generate UUID contextId | F16: 2 | G16: =F16/8 -> 0.25 | H16: Implemented / verify acceptance | I16: Planning estimate; not time logged
A17: VCCI-AI-04 | B17: VCCI Desktop | C17: Implement conversation context and session tracking | D17: 2 | E17: Track previousAgentId and lastAutoSelectedAgent | F17: 3 | G17: =F17/8 -> 0.375 | H17: Implemented / verify acceptance
A18: VCCI-AI-04 | B18: VCCI Desktop | C18: Implement conversation context and session tracking | D18: 3 | E18: Preserve context across messages | F18: 2 | G18: =F18/8 -> 0.25 | H18: Implemented / verify acceptance
A19: VCCI-AI-04 | B19: VCCI Desktop | C19: Implement conversation context and session tracking | D19: 4 | E19: Reset context for New Chat | F19: 2 | G19: =F19/8 -> 0.25 | H19: Implemented / verify acceptance
A20: VCCI-AI-04 | B20: VCCI Desktop | C20: Implement conversation context and session tracking | D20: 5 | E20: Test switching agents and sessions | F20: 3 | G20: =F20/8 -> 0.375 | H20: Implemented / verify acceptance
A21: VCCI-AI-05 | B21: VCCI Desktop | C21: Implement response and status handling | D21: 1 | E21: Show outgoing prompt and pending status | F21: 2 | G21: =F21/8 -> 0.25 | H21: Implemented / verify acceptance | I21: Planning estimate; not time logged
A22: VCCI-AI-05 | B22: VCCI Desktop | C22: Implement response and status handling | D22: 2 | E22: Render successful responses | F22: 2 | G22: =F22/8 -> 0.25 | H22: Implemented / verify acceptance
A23: VCCI-AI-05 | B23: VCCI Desktop | C23: Implement response and status handling | D23: 3 | E23: Handle timeouts and connection errors | F23: 2 | G23: =F23/8 -> 0.25 | H23: Implemented / verify acceptance
A24: VCCI-AI-05 | B24: VCCI Desktop | C24: Implement response and status handling | D24: 4 | E24: Test UI responsiveness | F24: 2 | G24: =F24/8 -> 0.25 | H24: Implemented / verify acceptance
A25: VCCI-AI-06 | B25: AI Core Discovery | C25: Integrate VCCI with AI Core agent discovery | D25: 1 | E25: Inspect AI Core discovery contract | F25: 3 | G25: =F25/8 -> 0.375 | H25: Implemented / verify acceptance | I25: Planning estimate; not time logged
A26: VCCI-AI-06 | B26: AI Core Discovery | C26: Integrate VCCI with AI Core agent discovery | D26: 2 | E26: Connect AIService and VCCIControlPanel | F26: 4 | G26: =F26/8 -> 0.5 | H26: Implemented / verify acceptance
A27: VCCI-AI-06 | B27: AI Core Discovery | C27: Integrate VCCI with AI Core agent discovery | D27: 3 | E27: Map identifiers, commands, and metadata | F27: 3 | G27: =F27/8 -> 0.375 | H27: Implemented / verify acceptance
A28: VCCI-AI-06 | B28: AI Core Discovery | C28: Integrate VCCI with AI Core agent discovery | D28: 4 | E28: Populate chatbot agent list | F28: 3 | G28: =F28/8 -> 0.375 | H28: Implemented / verify acceptance
A29: VCCI-AI-06 | B29: AI Core Discovery | C29: Integrate VCCI with AI Core agent discovery | D29: 5 | E29: Test single and multiple agent discovery | F29: 3 | G29: =F29/8 -> 0.375 | H29: Implemented / verify acceptance
A30: VCCI-AI-07 | B30: AI Core Discovery | C30: Extend GetCommandsRequest with endpoint mappings | D30: 1 | E30: Review existing command data structure | F30: 1 | G30: =F30/8 -> 0.125 | H30: Implemented / verify acceptance | I30: AI Core bba708e1
A31: VCCI-AI-07 | B31: AI Core Discovery | C31: Extend GetCommandsRequest with endpoint mappings | D31: 2 | E31: Add jAgentURLs map | F31: 2 | G31: =F31/8 -> 0.25 | H31: Implemented / verify acceptance
A32: VCCI-AI-07 | B32: AI Core Discovery | C32: Extend GetCommandsRequest with endpoint mappings | D32: 3 | E32: Implement setter and getter | F32: 1 | G32: =F32/8 -> 0.125 | H32: Implemented / verify acceptance
A33: VCCI-AI-07 | B33: AI Core Discovery | C33: Extend GetCommandsRequest with endpoint mappings | D33: 4 | E33: Populate mapping from discovery | F33: 2 | G33: =F33/8 -> 0.25 | H33: Implemented / verify acceptance
A34: VCCI-AI-07 | B34: AI Core Discovery | C34: Extend GetCommandsRequest with endpoint mappings | D34: 5 | E34: Verify serialized/received values | F34: 2 | G34: =F34/8 -> 0.25 | H34: Implemented / verify acceptance
A35: VCCI-AI-08 | B35: AI Core Discovery | C35: Cache AI Service agents and endpoint URLs | D35: 1 | E35: Add agent and URL caches | F35: 2 | G35: =F35/8 -> 0.25 | H35: Implemented / verify acceptance | I35: Planning estimate; not time logged
A36: VCCI-AI-08 | B36: AI Core Discovery | C36: Cache AI Service agents and endpoint URLs | D36: 2 | E36: Populate from AI Core responses | F36: 2 | G36: =F36/8 -> 0.25 | H36: Implemented / verify acceptance
A37: VCCI-AI-08 | B37: AI Core Discovery | C37: Cache AI Service agents and endpoint URLs | D37: 3 | E37: Refresh cache on demand | F37: 2 | G37: =F37/8 -> 0.25 | H37: Implemented / verify acceptance
A38: VCCI-AI-08 | B38: AI Core Discovery | C38: Cache AI Service agents and endpoint URLs | D38: 4 | E38: Guard against empty or stale entries | F38: 2 | G38: =F38/8 -> 0.25 | H38: Implemented / verify acceptance
A39: VCCI-AI-09 | B39: AI Core Discovery | C39: Implement agent metadata and skill models | D39: 1 | E39: Define AgentInfo fields | F39: 2 | G39: =F39/8 -> 0.25 | H39: Implemented / verify acceptance | I39: Planning estimate; not time logged
A40: VCCI-AI-09 | B40: AI Core Discovery | C40: Implement agent metadata and skill models | D40: 2 | E40: Define AgentSkillInfo capabilities | F40: 2 | G40: =F40/8 -> 0.25 | H40: Implemented / verify acceptance
...

Sheet Ticket Summary
A1: Ticket ID | B1: Epic | C1: Ticket / Task | D1: Total hours | E1: Total days | F1: Status | G1: Step count | H1: Detail source range
A2: VCCI-AI-01 | B2: VCCI Desktop | C2: Develop Java Swing AI Chatbot client | D2: =SUMIF('Detailed Steps'!$A$2:$A$125,A2,'Detailed Steps'!$F$2:$F$125) -> 24 | E2: =D2/8 -> 3 | F2: Implemented / verify acceptance | G2: 5 | H2: 'Detailed Steps'!F2:F6
A3: VCCI-AI-02 | B3: VCCI Desktop | C3: Implement agent selection and chat controls | D3: =SUMIF('Detailed Steps'!$A$2:$A$125,A3,'Detailed Steps'!$F$2:$F$125) -> 12 | E3: =D3/8 -> 1.5 | F3: Implemented / verify acceptance | G3: 5 | H3: 'Detailed Steps'!F7:F11
A4: VCCI-AI-03 | B4: VCCI Desktop | C4: Display dynamic friendly agent names | D4: =SUMIF('Detailed Steps'!$A$2:$A$125,A4,'Detailed Steps'!$F$2:$F$125) -> 8 | E4: =D4/8 -> 1 | F4: Implemented / verify acceptance | G4: 4 | H4: 'Detailed Steps'!F12:F15
A5: VCCI-AI-04 | B5: VCCI Desktop | C5: Implement conversation context and session tracking | D5: =SUMIF('Detailed Steps'!$A$2:$A$125,A5,'Detailed Steps'!$F$2:$F$125) -> 12 | E5: =D5/8 -> 1.5 | F5: Implemented / verify acceptance | G5: 5 | H5: 'Detailed Steps'!F16:F20
A6: VCCI-AI-05 | B6: VCCI Desktop | C6: Implement response and status handling | D6: =SUMIF('Detailed Steps'!$A$2:$A$125,A6,'Detailed Steps'!$F$2:$F$125) -> 8 | E6: =D6/8 -> 1 | F6: Implemented / verify acceptance | G6: 4 | H6: 'Detailed Steps'!F21:F24
A7: VCCI-AI-06 | B7: AI Core Discovery | C7: Integrate VCCI with AI Core agent discovery | D7: =SUMIF('Detailed Steps'!$A$2:$A$125,A7,'Detailed Steps'!$F$2:$F$125) -> 16 | E7: =D7/8 -> 2 | F7: Implemented / verify acceptance | G7: 5 | H7: 'Detailed Steps'!F25:F29
A8: VCCI-AI-07 | B8: AI Core Discovery | C8: Extend GetCommandsRequest with endpoint mappings | D8: =SUMIF('Detailed Steps'!$A$2:$A$125,A8,'Detailed Steps'!$F$2:$F$125) -> 8 | E8: =D8/8 -> 1 | F8: Implemented / verify acceptance | G8: 5 | H8: 'Detailed Steps'!F30:F34
A9: VCCI-AI-08 | B9: AI Core Discovery | C9: Cache AI Service agents and endpoint URLs | D9: =SUMIF('Detailed Steps'!$A$2:$A$125,A9,'Detailed Steps'!$F$2:$F$125) -> 8 | E9: =D9/8 -> 1 | F9: Implemented / verify acceptance | G9: 4 | H9: 'Detailed Steps'!F35:F38
A10: VCCI-AI-09 | B10: AI Core Discovery | C10: Implement agent metadata and skill models | D10: =SUMIF('Detailed Steps'!$A$2:$A$125,A10,'Detailed Steps'!$F$2:$F$125) -> 8 | E10: =D10/8 -> 1 | F10: Implemented / verify acceptance | G10: 4 | H10: 'Detailed Steps'!F39:F42
A11: VCCI-AI-10 | B11: AI Core Discovery | C11: Validate discovery refresh and failure recovery | D11: =SUMIF('Detailed Steps'!$A$2:$A$125,A11,'Detailed Steps'!$F$2:$F$125) -> 12 | E11: =D11/8 -> 1.5 | F11: Validation required | G11: 5 | H11: 'Detailed Steps'!F43:F47
A12: VCCI-AI-11 | B12: Intelligent Routing | C12: Implement manual routing to discovered endpoints | D12: =SUMIF('Detailed Steps'!$A$2:$A$125,A12,'Detailed Steps'!$F$2:$F$125) -> 12 | E12: =D12/8 -> 1.5 | F12: Implemented / verify acceptance | G12: 5 | H12: 'Detailed Steps'!F48:F52
A13: VCCI-AI-12 | B13: Intelligent Routing | C13: Implement prompt-based automatic agent selection | D13: =SUMIF('Detailed Steps'!$A$2:$A$125,A13,'Detailed Steps'!$F$2:$F$125) -> 24 | E13: =D13/8 -> 3 | F13: Implemented / verify acceptance | G13: 7 | H13: 'Detailed Steps'!F53:F59
... A26: VCCI-AI-25 | B26: Delivery / Testing | C26: Integration tests, documentation, and release evidence | D26: =SUMIF('Detailed Steps'!$A$2:$A$125,A26,'Detailed Steps'!$F$2:$F$125) -> 16 | E26: =D26/8 -> 2 | F26: Validation required | G26: 5 | H26: 'Detailed Steps'!F121:F125
A27: TOTAL | D27: =SUM(D2:D26) -> 336 | E27: =D27/8 -> 42

Sheet Epic Summary
A1: Epic | B1: Ticket count | C1: Estimated hours | D1: Estimated days
A2: VCCI Desktop | B2: =COUNTIF('Ticket Summary'!$B$2:$B$26,A2) -> 5 | C2: =SUMIF('Ticket Summary'!$B$2:$B$26,A2,'Ticket Summary'!$D$2:$D$26) -> 64 | D2: =C2/8 -> 8
A3: AI Core Discovery | B3: =COUNTIF('Ticket Summary'!$B$2:$B$26,A3) -> 5 | C3: =SUMIF('Ticket Summary'!$B$2:$B$26,A3,'Ticket Summary'!$D$2:$D$26) -> 52 | D3: =C3/8 -> 6.5
A4: Intelligent Routing | B4: =COUNTIF('Ticket Summary'!$B$2:$B$26,A4) -> 5 | C4: =SUMIF('Ticket Summary'!$B$2:$B$26,A4,'Ticket Summary'!$D$2:$D$26) -> 76 | D4: =C4/8 -> 9.5
A5: Python A2A / Cohere | B5: =COUNTIF('Ticket Summary'!$B$2:$B$26,A5) -> 5 | C5: =SUMIF('Ticket Summary'!$B$2:$B$26,A5,'Ticket Summary'!$D$2:$D$26) -> 88 | D5: =C5/8 -> 11
A6: Build / Runtime | B6: =COUNTIF('Ticket Summary'!$B$2:$B$26,A6) -> 3 | C6: =SUMIF('Ticket Summary'!$B$2:$B$26,A6,'Ticket Summary'!$D$2:$D$26) -> 28 | D6: =C6/8 -> 3.5
A7: Delivery / Testing | B7: =COUNTIF('Ticket Summary'!$B$2:$B$26,A7) -> 2 | C7: =SUMIF('Ticket Summary'!$B$2:$B$26,A7,'Ticket Summary'!$D$2:$D$26) -> 28 | D7: =C7/8 -> 3.5
A8: TOTAL | B8: =SUM(B2:B7) -> 25 | C8: =SUM(C2:C7) -> 336 | D8: =SUM(D2:D7) -> 42
A10: Planning assumptions | B10: Value
A11: Hours per day | B11: 8
A12: Contingency low | B12: 0.15
A13: Contingency high | B13: 0.2
A15: Total with 15% contingency (hours) | B15: =C8*(1+B12) -> 386.4
A16: Total with 20% contingency (hours) | B16: =C8*(1+B13) -> 403.2

Sheet Read Me
A1: VCCI–Cohere AI Integration — Effort Planning
A2: Workbook purpose | B2: Retrospective planning estimates with per-step breakdown for 25 proposed GitLab tickets.
A3: Detailed Steps | B3: One row per implementation step, with estimated hours and calculated days.
A4: Ticket Summary | B4: One row per GitLab ticket; total effort calculated from Detailed Steps.
A5: Epic Summary | B5: Formula-driven epic totals, contingency assumptions, and chart.
A6: Estimate basis | B6: 1 developer-day = 8 hours; estimates are not actual time worked.
A7: Status caveat | B7: Implemented indicates prior demonstration; verify acceptance and CI before closure.
A8: Scope | B8: Java Swing VCCI, AI Core Micronaut, FastAPI/A2A, Cohere North, routing, Git recovery.

Sheet Sheet1
